[2023-12-11T21:15:30.269+0000] {taskinstance.py:1159} INFO - Dependencies all met for dep_context=non-requeueable deps ti=<TaskInstance: ETL_NASA.load_data_to_redshift_task scheduled__2023-10-10T00:00:00+00:00 [queued]>
[2023-12-11T21:15:30.291+0000] {taskinstance.py:1159} INFO - Dependencies all met for dep_context=requeueable deps ti=<TaskInstance: ETL_NASA.load_data_to_redshift_task scheduled__2023-10-10T00:00:00+00:00 [queued]>
[2023-12-11T21:15:30.293+0000] {taskinstance.py:1361} INFO - Starting attempt 1 of 2
[2023-12-11T21:15:30.326+0000] {taskinstance.py:1382} INFO - Executing <Task(PythonOperator): load_data_to_redshift_task> on 2023-10-10 00:00:00+00:00
[2023-12-11T21:15:30.336+0000] {standard_task_runner.py:57} INFO - Started process 115 to run task
[2023-12-11T21:15:30.344+0000] {standard_task_runner.py:84} INFO - Running: ['***', 'tasks', 'run', 'ETL_NASA', 'load_data_to_redshift_task', 'scheduled__2023-10-10T00:00:00+00:00', '--job-id', '64', '--raw', '--subdir', 'DAGS_FOLDER/dag_nasa.py', '--cfg-path', '/tmp/tmpn5oa5hn3']
[2023-12-11T21:15:30.347+0000] {standard_task_runner.py:85} INFO - Job 64: Subtask load_data_to_redshift_task
[2023-12-11T21:15:30.461+0000] {task_command.py:416} INFO - Running <TaskInstance: ETL_NASA.load_data_to_redshift_task scheduled__2023-10-10T00:00:00+00:00 [running]> on host d9b326dafe4c
[2023-12-11T21:15:30.601+0000] {taskinstance.py:1662} INFO - Exporting env vars: AIRFLOW_CTX_DAG_OWNER='Jose Daniel PÃ©rez' AIRFLOW_CTX_DAG_ID='ETL_NASA' AIRFLOW_CTX_TASK_ID='load_data_to_redshift_task' AIRFLOW_CTX_EXECUTION_DATE='2023-10-10T00:00:00+00:00' AIRFLOW_CTX_TRY_NUMBER='1' AIRFLOW_CTX_DAG_RUN_ID='scheduled__2023-10-10T00:00:00+00:00'
[2023-12-11T21:15:30.607+0000] {taskinstance.py:1937} ERROR - Task failed with exception
Traceback (most recent call last):
  File "/home/airflow/.local/lib/python3.8/site-packages/airflow/operators/python.py", line 192, in execute
    return_value = self.execute_callable()
  File "/home/airflow/.local/lib/python3.8/site-packages/airflow/operators/python.py", line 209, in execute_callable
    return self.python_callable(*self.op_args, **self.op_kwargs)
TypeError: load_data_to_redshift() takes 2 positional arguments but 3 were given
[2023-12-11T21:15:30.624+0000] {taskinstance.py:1400} INFO - Marking task as UP_FOR_RETRY. dag_id=ETL_NASA, task_id=load_data_to_redshift_task, execution_date=20231010T000000, start_date=20231211T211530, end_date=20231211T211530
[2023-12-11T21:15:30.654+0000] {standard_task_runner.py:104} ERROR - Failed to execute job 64 for task load_data_to_redshift_task (load_data_to_redshift() takes 2 positional arguments but 3 were given; 115)
[2023-12-11T21:15:30.716+0000] {local_task_job_runner.py:228} INFO - Task exited with return code 1
[2023-12-11T21:15:30.766+0000] {taskinstance.py:2778} INFO - 0 downstream tasks scheduled from follow-on schedule check
