[2023-12-11T21:20:21.078+0000] {taskinstance.py:1159} INFO - Dependencies all met for dep_context=non-requeueable deps ti=<TaskInstance: ETL_NASA.load_data_to_redshift_task scheduled__2023-11-10T00:00:00+00:00 [queued]>
[2023-12-11T21:20:21.103+0000] {taskinstance.py:1159} INFO - Dependencies all met for dep_context=requeueable deps ti=<TaskInstance: ETL_NASA.load_data_to_redshift_task scheduled__2023-11-10T00:00:00+00:00 [queued]>
[2023-12-11T21:20:21.104+0000] {taskinstance.py:1361} INFO - Starting attempt 1 of 2
[2023-12-11T21:20:21.136+0000] {taskinstance.py:1382} INFO - Executing <Task(PythonOperator): load_data_to_redshift_task> on 2023-11-10 00:00:00+00:00
[2023-12-11T21:20:21.151+0000] {standard_task_runner.py:57} INFO - Started process 225 to run task
[2023-12-11T21:20:21.159+0000] {standard_task_runner.py:84} INFO - Running: ['***', 'tasks', 'run', 'ETL_NASA', 'load_data_to_redshift_task', 'scheduled__2023-11-10T00:00:00+00:00', '--job-id', '82', '--raw', '--subdir', 'DAGS_FOLDER/dag_nasa.py', '--cfg-path', '/tmp/tmpa9ep3an7']
[2023-12-11T21:20:21.163+0000] {standard_task_runner.py:85} INFO - Job 82: Subtask load_data_to_redshift_task
[2023-12-11T21:20:21.303+0000] {task_command.py:416} INFO - Running <TaskInstance: ETL_NASA.load_data_to_redshift_task scheduled__2023-11-10T00:00:00+00:00 [running]> on host d9b326dafe4c
[2023-12-11T21:20:21.465+0000] {taskinstance.py:1662} INFO - Exporting env vars: AIRFLOW_CTX_DAG_OWNER='Jose Daniel PÃ©rez' AIRFLOW_CTX_DAG_ID='ETL_NASA' AIRFLOW_CTX_TASK_ID='load_data_to_redshift_task' AIRFLOW_CTX_EXECUTION_DATE='2023-11-10T00:00:00+00:00' AIRFLOW_CTX_TRY_NUMBER='1' AIRFLOW_CTX_DAG_RUN_ID='scheduled__2023-11-10T00:00:00+00:00'
[2023-12-11T21:20:21.470+0000] {taskinstance.py:1937} ERROR - Task failed with exception
Traceback (most recent call last):
  File "/home/airflow/.local/lib/python3.8/site-packages/airflow/operators/python.py", line 192, in execute
    return_value = self.execute_callable()
  File "/home/airflow/.local/lib/python3.8/site-packages/airflow/operators/python.py", line 209, in execute_callable
    return self.python_callable(*self.op_args, **self.op_kwargs)
TypeError: load_data_to_redshift() takes 2 positional arguments but 3 were given
[2023-12-11T21:20:21.486+0000] {taskinstance.py:1400} INFO - Marking task as UP_FOR_RETRY. dag_id=ETL_NASA, task_id=load_data_to_redshift_task, execution_date=20231110T000000, start_date=20231211T212021, end_date=20231211T212021
[2023-12-11T21:20:21.512+0000] {standard_task_runner.py:104} ERROR - Failed to execute job 82 for task load_data_to_redshift_task (load_data_to_redshift() takes 2 positional arguments but 3 were given; 225)
[2023-12-11T21:20:21.532+0000] {local_task_job_runner.py:228} INFO - Task exited with return code 1
[2023-12-11T21:20:21.567+0000] {taskinstance.py:2778} INFO - 0 downstream tasks scheduled from follow-on schedule check
