[2023-12-11T00:54:49.494+0000] {taskinstance.py:1159} INFO - Dependencies all met for dep_context=non-requeueable deps ti=<TaskInstance: ETL_NASA.get_asteroid_data_task scheduled__2023-10-10T00:00:00+00:00 [queued]>
[2023-12-11T00:54:49.579+0000] {taskinstance.py:1159} INFO - Dependencies all met for dep_context=requeueable deps ti=<TaskInstance: ETL_NASA.get_asteroid_data_task scheduled__2023-10-10T00:00:00+00:00 [queued]>
[2023-12-11T00:54:49.592+0000] {taskinstance.py:1361} INFO - Starting attempt 1 of 2
[2023-12-11T00:54:49.725+0000] {taskinstance.py:1382} INFO - Executing <Task(PythonOperator): get_asteroid_data_task> on 2023-10-10 00:00:00+00:00
[2023-12-11T00:54:49.790+0000] {standard_task_runner.py:57} INFO - Started process 116 to run task
[2023-12-11T00:54:49.833+0000] {standard_task_runner.py:84} INFO - Running: ['***', 'tasks', 'run', 'ETL_NASA', 'get_asteroid_data_task', 'scheduled__2023-10-10T00:00:00+00:00', '--job-id', '15', '--raw', '--subdir', 'DAGS_FOLDER/dag_nasa.py', '--cfg-path', '/tmp/tmppunx8tq9']
[2023-12-11T00:54:49.838+0000] {standard_task_runner.py:85} INFO - Job 15: Subtask get_asteroid_data_task
[2023-12-11T00:54:50.103+0000] {task_command.py:416} INFO - Running <TaskInstance: ETL_NASA.get_asteroid_data_task scheduled__2023-10-10T00:00:00+00:00 [running]> on host d9b326dafe4c
[2023-12-11T00:54:50.958+0000] {taskinstance.py:1662} INFO - Exporting env vars: AIRFLOW_CTX_DAG_OWNER='Jose Daniel PÃ©rez' AIRFLOW_CTX_DAG_ID='ETL_NASA' AIRFLOW_CTX_TASK_ID='get_asteroid_data_task' AIRFLOW_CTX_EXECUTION_DATE='2023-10-10T00:00:00+00:00' AIRFLOW_CTX_TRY_NUMBER='1' AIRFLOW_CTX_DAG_RUN_ID='scheduled__2023-10-10T00:00:00+00:00'
[2023-12-11T00:55:22.043+0000] {taskinstance.py:1937} ERROR - Task failed with exception
Traceback (most recent call last):
  File "/home/airflow/.local/lib/python3.8/site-packages/requests/models.py", line 971, in json
    return complexjson.loads(self.text, **kwargs)
  File "/usr/local/lib/python3.8/json/__init__.py", line 357, in loads
    return _default_decoder.decode(s)
  File "/usr/local/lib/python3.8/json/decoder.py", line 337, in decode
    obj, end = self.raw_decode(s, idx=_w(s, 0).end())
  File "/usr/local/lib/python3.8/json/decoder.py", line 355, in raw_decode
    raise JSONDecodeError("Expecting value", s, err.value) from None
json.decoder.JSONDecodeError: Expecting value: line 1 column 1 (char 0)

During handling of the above exception, another exception occurred:

Traceback (most recent call last):
  File "/home/airflow/.local/lib/python3.8/site-packages/airflow/operators/python.py", line 192, in execute
    return_value = self.execute_callable()
  File "/home/airflow/.local/lib/python3.8/site-packages/airflow/operators/python.py", line 209, in execute_callable
    return self.python_callable(*self.op_args, **self.op_kwargs)
  File "/opt/airflow/dags/scripts/etl_functions.py", line 14, in get_asteroid_data
    data = response.json()
  File "/home/airflow/.local/lib/python3.8/site-packages/requests/models.py", line 975, in json
    raise RequestsJSONDecodeError(e.msg, e.doc, e.pos)
requests.exceptions.JSONDecodeError: Expecting value: line 1 column 1 (char 0)
[2023-12-11T00:55:22.223+0000] {taskinstance.py:1400} INFO - Marking task as UP_FOR_RETRY. dag_id=ETL_NASA, task_id=get_asteroid_data_task, execution_date=20231010T000000, start_date=20231211T005449, end_date=20231211T005522
[2023-12-11T00:55:22.318+0000] {standard_task_runner.py:104} ERROR - Failed to execute job 15 for task get_asteroid_data_task (Expecting value: line 1 column 1 (char 0); 116)
[2023-12-11T00:55:22.400+0000] {local_task_job_runner.py:228} INFO - Task exited with return code 1
[2023-12-11T00:55:22.492+0000] {taskinstance.py:2778} INFO - 0 downstream tasks scheduled from follow-on schedule check
